Workbook

Sheet 01_Raw_Operations
A1: Record_ID | B1: Date | C1: Region | D1: Team | E1: Opening_Backlog | F1: Requests_Received | G1: Total_Workload | H1: Requests_Completed | I1: Closing_Backlog | J1: Incident_Count | K1: High_Critical_Incidents | L1: Average_Completion_Days | M1: SLA_Compliance | N1: Quality_Pass_Rate | O1: Customer_Satisfaction | P1: Staff_Utilisation | Q1: Completion_Rate
A2: OPS-100001 | B2: 46023 | C2: Scotland | D2: Workplace Services | E2: 9 | F2: 55 | G2: 64 | H2: 34 | I2: 30 | J2: 0 | K2: 0 | L2: 4.3 | M2: 0.789 | N2: 0.951 | O2: 3.5 | P2: 0.705 | Q2: 0.531
A3: OPS-100002 | B3: 46023 | C3: Scotland | D3: Facilities Response | E3: 8 | F3: 51 | G3: 59 | H3: 57 | I3: 2 | J3: 0 | K3: 0 | L3: 2.1 | M3: 0.995 | N3: 0.992 | O3: 4.4 | P3: 0.71 | Q3: 0.966
A4: OPS-100003 | B4: 46023 | C4: Scotland | D4: Estates Support | E4: 11 | F4: 62 | G4: 73 | H4: 39 | I4: 34 | J4: 0 | K4: 0 | L4: 4.3 | M4: 0.719 | N4: 0.973 | O4: 3.4 | P4: 0.786 | Q4: 0.534
A5: OPS-100004 | B5: 46023 | C5: Scotland | D5: Workplace Projects | E5: 12 | F5: 35 | G5: 47 | H5: 46 | I5: 1 | J5: 0 | K5: 0 | L5: 1.2 | M5: 0.972 | N5: 0.996 | O5: 4.4 | P5: 0.777 | Q5: 0.979
A6: OPS-100005 | B6: 46023 | C6: North East | D6: Workplace Services | E6: 12 | F6: 49 | G6: 61 | H6: 44 | I6: 17 | J6: 0 | K6: 0 | L6: 2.9 | M6: 0.848 | N6: 0.967 | O6: 3.9 | P6: 0.692 | Q6: 0.721
A7: OPS-100006 | B7: 46023 | C7: North East | D7: Facilities Response | E7: 12 | F7: 26 | G7: 38 | H7: 38 | I7: 0 | J7: 0 | K7: 0 | L7: 1.4 | M7: 0.95 | N7: 1 | O7: 4.8 | P7: 0.706 | Q7: 1
A8: OPS-100007 | B8: 46023 | C8: North East | D8: Estates Support | E8: 12 | F8: 30 | G8: 42 | H8: 17 | I8: 25 | J8: 0 | K8: 0 | L8: 4 | M8: 0.856 | N8: 0.981 | O8: 3.4 | P8: 0.709 | Q8: 0.405
A9: OPS-100008 | B9: 46023 | C9: North East | D9: Workplace Projects | E9: 11 | F9: 27 | G9: 38 | H9: 28 | I9: 10 | J9: 0 | K9: 0 | L9: 2.2 | M9: 0.928 | N9: 0.979 | O9: 4.5 | P9: 0.774 | Q9: 0.737
A10: OPS-100009 | B10: 46023 | C10: North West | D10: Workplace Services | E10: 9 | F10: 42 | G10: 51 | H10: 36 | I10: 15 | J10: 0 | K10: 0 | L10: 2.6 | M10: 0.86 | N10: 1 | O10: 4.1 | P10: 0.779 | Q10: 0.706
A11: OPS-100010 | B11: 46023 | C11: North West | D11: Facilities Response | E11: 6 | F11: 46 | G11: 52 | H11: 27 | I11: 25 | J11: 0 | K11: 0 | L11: 3.8 | M11: 0.814 | N11: 1 | O11: 3.6 | P11: 0.783 | Q11: 0.519
A12: OPS-100011 | B12: 46023 | C12: North West | D12: Estates Support | E12: 5 | F12: 44 | G12: 49 | H12: 17 | I12: 32 | J12: 1 | K12: 0 | L12: 3.9 | M12: 0.725 | N12: 0.97 | O12: 3.1 | P12: 0.667 | Q12: 0.347
A13: OPS-100012 | B13: 46023 | C13: North West | D13: Workplace Projects | E13: 14 | F13: 36 | G13: 50 | H13: 47 | I13: 3 | J13: 0 | K13: 0 | L13: 2.1 | M13: 0.957 | N13: 0.964 | O13: 4.3 | P13: 0.723 | Q13: 0.94
... A351: OPS-100350 | B351: 46037 | C351: Midlands | D351: Facilities Response | E351: 150 | F351: 47 | G351: 197 | H351: 30 | I351: 167 | J351: 0 | K351: 0 | L351: 8 | M351: 0.6 | N351: 0.983 | O351: 2.5 | P351: 0.788 | Q351: 0.152
A352: OPS-100351 | B352: 46037 | C352: Midlands | D352: Estates Support | E352: 75 | F352: 34 | G352: 109 | H352: 36 | I352: 73 | J352: 0 | K352: 0 | L352: 7.2 | M352: 0.6 | N352: 0.979 | P352: 0.788 | Q352: 0.33
A353: OPS-100352 | B353: 46037 | C353: Midlands | D353: Workplace Projects | E353: 0 | F353: 34 | G353: 34 | H353: 34 | I353: 0 | J353: 0 | K353: 0 | L353: 1.8 | M353: 0.989 | N353: 1 | O353: 4.7 | P353: 0.72 | Q353: 1
A354: OPS-100353 | B354: 46037 | C354: South West | D354: Workplace Services | E354: 174 | F354: 54 | G354: 228 | H354: 25 | I354: 203 | J354: 0 | K354: 0 | L354: 8 | M354: 0.6 | N354: 0.993 | O354: 2.5 | P354: 0.703 | Q354: 0.11
A355: OPS-100354 | B355: 46037 | C355: South West | D355: Facilities Response | E355: 0 | F355: 39 | G355: 39 | H355: 39 | I355: 0 | J355: 0 | K355: 0 | L355: 1.1 | M355: 1 | N355: 0.977 | O355: 4.8 | P355: 0.689 | Q355: 1
A356: OPS-100355 | B356: 46037 | C356: South West | D356: Estates Support | E356: 16 | F356: 32 | G356: 48 | H356: 48 | I356: 0 | J356: 0 | K356: 0 | L356: 1.7 | M356: 0.976 | N356: 0.959 | O356: 4.6 | P356: 0.649 | Q356: 1
A357: OPS-100356 | B357: 46037 | C357: South West | D357: Workplace Projects | E357: 0 | F357: 34 | G357: 34 | H357: 34 | I357: 0 | J357: 0 | K357: 0 | L357: 1.9 | M357: 0.918 | N357: 0.983 | O357: 4.6 | P357: 0.673 | Q357: 1
A358: OPS-100357 | B358: 46037 | C358: South East | D358: Workplace Services | E358: 11 | F358: 49 | G358: 60 | H358: 57 | I358: 3 | J358: 1 | K358: 0 | L358: 1.8 | M358: 0.942 | N358: 0.972 | O358: 4.4 | P358: 0.669 | Q358: 0.95
A359: OPS-100358 | B359: 46037 | C359: South East | D359: Facilities Response | E359: 388 | F359: 47 | G359: 435 | H359: 21 | I359: 414 | J359: 0 | K359: 0 | L359: 8 | M359: 0.6 | N359: 0.982 | O359: 2.5 | P359: 0.751 | Q359: 0.048
A360: OPS-100359 | B360: 46037 | C360: South East | D360: Estates Support | E360: 12 | F360: 36 | G360: 48 | H360: 48 | I360: 0 | J360: 1 | K360: 0 | L360: 1.8 | M360: 0.887 | N360: 0.987 | O360: 4.7 | P360: 0.695 | Q360: 1
A361: OPS-100360 | B361: 46037 | C361: South East | D361: Workplace Projects | E361: 143 | F361: 30 | G361: 173 | H361: 23 | I361: 150 | J361: 0 | K361: 0 | L361: 8 | M361: 0.6 | N361: 1 | O361: 2.5 | P361: 0.719 | Q361: 0.133
A362: OPS-100361 | B362: 46037 | C362: Wales | D362: Workplace Services | E362: 198 | F362: 47 | G362: 245 | H362: 24 | I362: 221 | J362: 0 | K362: 0 | L362: 8 | M362: 0.6 | N362: 0.972 | O362: 2.5 | P362: 0.771 | Q362: 0.098
A363: OPS-100362 | B363: 46037 | C363: Wales | D363: Facilities Response | E363: 134 | F363: 37 | G363: 171 | H363: 30 | I363: 141 | J363: 0 | K363: 0 | L363: 8 | M363: 0.6 | N363: 1 | O363: 2.5 | P363: 0.706 | Q363: 0.175
A364: OPS-100363 | B364: 46037 | C364: Wales | D364: Estates Support | E364: 100 | F364: 57 | G364: 157 | H364: 27 | I364: 130 | J364: 0 | K364: 0 | L364: 8 | M364: 0.6 | N364: 0.98 | O364: 2.5 | P364: 0.755 | Q364: 0.172
... A621: OPS-100620 | B621: 46051 | C621: Scotland | D621: Workplace Projects | E621: 0 | F621: 31 | G621: 31 | H621: 31 | I621: 0 | J621: 0 | K621: 0 | L621: 1.7 | M621: 0.954 | N621: 1 | O621: 4.7 | P621: 0.777 | Q621: 1
A622: OPS-100621 | B622: 46051 | C622: North East | D622: Workplace Services | E622: 0 | F622: 37 | G622: 37 | H622: 37 | I622: 0 | J622: 0 | K622: 0 | L622: 1.6 | N622: 1 | O622: 4.5 | P622: 0.692 | Q622: 1
A623: OPS-100622 | B623: 46051 | C623: North East | D623: Facilities Response | E623: 11 | F623: 47 | G623: 58 | H623: 53 | I623: 5 | J623: 0 | K623: 0 | L623: 2.7 | M623: 0.938 | N623: 1 | O623: 4.6 | P623: 0.706 | Q623: 0.914
A624: OPS-100623 | B624: 46051 | C624: North East | D624: Estates Support | E624: 463 | F624: 41 | G624: 504 | H624: 20 | I624: 484 | J624: 0 | K624: 0 | L624: 8 | M624: 0.6 | N624: 0.992 | O624: 2.5 | P624: 0.709 | Q624: 0.04
A625: OPS-100624 | B625: 46051 | C625: North East | D625: Workplace Projects | E625: 24 | F625: 27 | G625: 51 | H625: 30 | I625: 21 | J625: 0 | K625: 0 | L625: 2.9 | M625: 0.825 | N625: 0.98 | O625: 3.8 | P625: 0.774 | Q625: 0.588
A626: OPS-100625 | B626: 46051 | C626: North West | D626: Workplace Services | E626: 229 | F626: 20 | G626: 249 | H626: 35 | I626: 214 | J626: 0 | K626: 0 | L626: 8 | M626: 0.6 | N626: 0.98 | O626: 2.5 | P626: 0.779 | Q626: 0.141
A627: OPS-100626 | B627: 46051 | C627: North West | D627: Facilities Response | E627: 375 | F627: 44 | G627: 419 | H627: 27 | I627: 392 | J627: 1 | K627: 0 | L627: 8 | M627: 0.6 | N627: 0.985 | O627: 2.5 | P627: 0.783 | Q627: 0.064
A628: OPS-100627 | B628: 46051 | C628: North West | D628: Estates Support | E628: 497 | F628: 51 | G628: 548 | H628: 18 | I628: 530 | J628: 1 | K628: 0 | L628: 8 | M628: 0.6 | N628: 0.983 | O628: 2.5 | P628: 0.667 | Q628: 0.033
A629: OPS-100628 | B629: 46051 | C629: North West | D629: Workplace Projects | E629: 0 | F629: 39 | G629: 39 | H629: 39 | I629: 0 | J629: 0 | K629: 0 | L629: 1.2 | M629: 0.932 | N629: 0.99 | O629: 4.9 | P629: 0.723 | Q629: 1
A630: OPS-100629 | B630: 46051 | C630: Midlands | D630: Workplace Services | E630: 2 | F630: 45 | G630: 47 | H630: 45 | I630: 2 | J630: 0 | K630: 0 | L630: 1.5 | M630: 0.975 | N630: 0.993 | O630: 4.3 | P630: 0.814 | Q630: 0.957
A631: OPS-100630 | B631: 46051 | C631: Midlands | D631: Facilities Response | E631: 244 | F631: 44 | G631: 288 | H631: 35 | I631: 253 | J631: 0 | K631: 0 | L631: 8 | M631: 0.6 | N631: 0.964 | O631: 2.5 | P631: 0.788 | Q631: 0.122
A632: OPS-100631 | B632: 46051 | C632: Midlands | D632: Estates Support | E632: 84 | F632: 66 | G632: 150 | H632: 36 | I632: 114 | J632: 0 | K632: 0 | L632: 8 | M632: 0.6 | N632: 1 | O632: 2.5 | P632: 0.788 | Q632: 0.24
A633: OPS-100632 | B633: 46051 | C633: Midlands | D633: Workplace Projects | E633: 0 | F633: 34 | G633: 34 | H633: 34 | I633: 0 | J633: 0 | K633: 0 | L633: 1.8 | M633: 0.997 | N633: 0.999 | O633: 4.7 | P633: 0.72 | Q633: 1
...

Sheet 02_Raw_Staffing
A1: Staff_Record_ID | B1: Month | C1: Region | D1: Team | E1: Headcount | F1: Working_Days | G1: Available_Hours | H1: Absence_Hours | I1: Training_Hours | J1: Productive_Hours | K1: Staff_Utilisation
A2: STAFF-2001 | B2: 46023 | C2: Scotland | D2: Workplace Services | E2: 14 | F2: 22 | G2: 2279.2 | H2: 220.1 | I2: 89.5 | J2: 1606.8 | K2: 0.705
A3: STAFF-2002 | B3: 46054 | C3: Scotland | D3: Workplace Services | E3: 14 | F3: 20 | G3: 2072 | H3: 84.8 | I3: 25.5 | J3: 1684.3 | K3: 0.813
A4: STAFF-2003 | B4: 46082 | C4: Scotland | D4: Workplace Services | E4: 14 | F4: 22 | G4: 2279.2 | H4: 91.2 | I4: 82.1 | J4: 1535.3 | K4: 0.674
A5: STAFF-2004 | B5: 46113 | C5: Scotland | D5: Workplace Services | E5: 14 | F5: 22 | G5: 2279.2 | H5: 218.1 | I5: 22.9 | J5: 1791.1 | K5: 0.786
A6: STAFF-2005 | B6: 46143 | C6: Scotland | D6: Workplace Services | E6: 13 | F6: 21 | G6: 2020.2 | H6: 103.6 | I6: 62.6 | J6: 1463 | K6: 0.724
A7: STAFF-2006 | B7: 46174 | C7: Scotland | D7: Workplace Services | E7: 13 | F7: 22 | G7: 2116.4 | H7: 141.2 | I7: 55 | J7: 1396.9 | K7: 0.66
A8: STAFF-2007 | B8: 46023 | C8: Scotland | D8: Facilities Response | E8: 19 | F8: 22 | G8: 3093.2 | H8: 175.6 | I8: 152.6 | J8: 2197.3 | K8: 0.71
A9: STAFF-2008 | B9: 46054 | C9: Scotland | D9: Facilities Response | E9: 20 | F9: 20 | G9: 2960 | H9: 214.7 | I9: 49.8 | J9: 1968.8 | K9: 0.665
A10: STAFF-2009 | B10: 46082 | C10: Scotland | D10: Facilities Response | E10: 19 | F10: 22 | G10: 3093.2 | H10: 296.8 | I10: 100.6 | J10: 2107.2 | K10: 0.681
A11: STAFF-2010 | B11: 46113 | C11: Scotland | D11: Facilities Response | E11: 19 | F11: 22 | G11: 3093.2 | H11: 113.9 | I11: 115.6 | J11: 2263.5 | K11: 0.732
A12: STAFF-2011 | B12: 46143 | C12: Scotland | D12: Facilities Response | E12: 19 | F12: 21 | G12: 2952.6 | H12: 190.9 | I12: 33.6 | J12: 2361.1 | K12: 0.8
A13: STAFF-2012 | B13: 46174 | C13: Scotland | D13: Facilities Response | E13: 19 | F13: 22 | G13: 3093.2 | H13: 132.3 | I13: 124.4 | J13: 2235.2 | K13: 0.723
... A81: STAFF-2080 | B81: 46054 | C81: Midlands | D81: Facilities Response | E81: 12 | F81: 20 | G81: 1776 | H81: 83.1 | I81: 24.4 | J81: 1250.1 | K81: 0.704
A82: STAFF-2081 | B82: 46082 | C82: Midlands | D82: Facilities Response | F82: 22 | G82: 2116.4 | H82: 105 | I82: 102 | J82: 1600.2 | K82: 0.756
A83: STAFF-2082 | B83: 46113 | C83: Midlands | D83: Facilities Response | E83: 13 | F83: 22 | G83: 2116.4 | H83: 154.1 | I83: 56.7 | J83: 1447.6 | K83: 0.684
A84: STAFF-2083 | B84: 46143 | C84: Midlands | D84: Facilities Response | E84: 12 | F84: 21 | G84: 1864.8 | H84: 154.9 | I84: 19.7 | J84: 1248.3 | K84: 0.669
A85: STAFF-2084 | B85: 46174 | C85: Midlands | D85: Facilities Response | E85: 13 | F85: 22 | G85: 2116.4 | H85: 77.4 | I85: 47.5 | J85: 1746 | K85: 0.825
A86: STAFF-2085 | B86: 46023 | C86: Midlands | D86: Estates Support | E86: 12 | F86: 22 | G86: 1953.6 | H86: 61 | I86: 79.2 | J86: 1539.8 | K86: 0.788
A87: STAFF-2086 | B87: 46054 | C87: Midlands | D87: Estates Support | E87: 12 | F87: 20 | G87: 1776 | H87: 74.8 | I87: 48.6 | J87: 1295.2 | K87: 0.729
A88: STAFF-2087 | B88: 46082 | C88: Midlands | D88: Estates Support | E88: 12 | F88: 22 | G88: 1953.6 | H88: 188.4 | I88: 88.8 | J88: 1277 | K88: 0.654
A89: STAFF-2088 | B89: 46113 | C89: Midlands | D89: Estates Support | E89: 12 | F89: 22 | G89: 1953.6 | H89: 144.2 | I89: 58.9 | J89: 1500.2 | K89: 0.768
A90: STAFF-2089 | B90: 46143 | C90: Midlands | D90: Estates Support | E90: 13 | F90: 21 | G90: 2020.2 | H90: 157.3 | I90: 70 | J90: 1561.7 | K90: 0.773
A91: STAFF-2090 | B91: 46174 | C91: Midlands | D91: Estates Support | E91: 12 | F91: 22 | G91: 1953.6 | H91: 62.2 | I91: 65.3 | J91: 1589.5 | K91: 0.814
A92: STAFF-2091 | B92: 46023 | C92: Midlands | D92: Workplace Projects | E92: 15 | F92: 22 | G92: 2442 | H92: 139.6 | I92: 87.3 | J92: 1757.3 | K92: 0.72
A93: STAFF-2092 | B93: 46054 | C93: Midlands | D93: Workplace Projects | E93: 15 | F93: 20 | G93: 2220 | H93: 194.1 | I93: 77.8 | J93: 1658.4 | K93: 0.747
A94: STAFF-2093 | B94: 46082 | C94: Midlands | D94: Workplace Projects | E94: 15 | F94: 22 | G94: 2442 | H94: 108.6 | I94: 51.2 | J94: 1721.5 | K94: 0.705
... A169: STAFF-2168 | B169: 46174 | C169: Wales | D169: Workplace Projects | E169: 16 | F169: 22 | G169: 2604.8 | H169: 121.4 | I169: 36.7 | J169: 1821.5 | K169: 0.699

Sheet 03_Raw_Incidents
A1: Incident_ID | B1: Date | C1: Region | D1: Team | E1: Incident_Type | F1: Severity | G1: Status | H1: Response_Time_Hours | I1: Resolution_Time_Hours | J1: Lesson_or_Action
A2: INC-00001 | B2: 46134 | C2: North East | D2: Estates Support | E2: Process failure | F2: Low | G2: Closed | H2: 0.6 | I2: 10 | J2: Documentation updated
A3: INC-00002 | B3: 46058 | C3: Wales | D3: Facilities Response | E3: Data quality issue | F3: Low | G3: Closed | H3: 7.4 | I3: 28.8 | J3: Process updated
A4: INC-00003 | B4: 46116 | C4: North East | D4: Estates Support | E4: Supplier delay | F4: High | G4: Closed | H4: 8.1 | I4: 18.2 | J4: No further action
A5: INC-00004 | B5: 46155 | C5: North East | D5: Facilities Response | E5: Data quality issue | F5: Medium | G5: Closed | H5: 7.2 | I5: 20.8 | J5: Process updated
A6: INC-00005 | B6: 46112 | C6: South East | D6: Facilities Response | E6: Staffing shortage | F6: Medium | G6: Open | H6: 2.4 | I6: 18.6
A7: INC-00006 | B7: 46156 | C7: North West | D7: Facilities Response | E7: Supplier delay | F7: Medium | G7: Open | H7: 1.6 | I7: 22.4
A8: INC-00007 | B8: 46106 | C8: North East | D8: Workplace Services | E8: System outage | F8: Low | G8: Closed | H8: 2.6 | I8: 14.3 | J8: Supplier action
A9: INC-00008 | B9: 46116 | C9: Scotland | D9: Workplace Services | E9: Data quality issue | F9: High | G9: Closed | H9: 2 | I9: 42.2 | J9: Process updated
A10: INC-00009 | B10: 46184 | C10: North East | D10: Estates Support | E10: Health & safety issue | F10: high | G10: Open | H10: 16.5 | I10: 21.1
A11: INC-00010 | B11: 46127 | C11: South East | D11: Workplace Projects | E11: Building issue | F11: Low | G11: In Progress | H11: 6.2 | I11: 20
A12: INC-00011 | B12: 46176 | C12: Wales | D12: Workplace Services | E12: System outage | F12: High | G12: Closed | H12: 15.3 | I12: 33 | J12: Supplier action
A13: INC-00012 | B13: 46147 | C13: North West | D13: Estates Support | E13: System outage | F13: Low | G13: Closed | H13: 1.9 | I13: 8.2 | J13: Training required
A14: INC-00013 | B14: 46075 | C14: Wales | D14: Estates Support | E14: Process failure | F14: Medium | G14: Closed | H14: 5.4 | I14: 12.7 | J14: No further action
A15: INC-00014 | B15: 46037 | C15: South East | D15: Workplace Services | E15: Customer escalation | F15: Medium | G15: Closed | H15: 8.3 | I15: 11.3 | J15: Process updated
A16: INC-00015 | B16: 46177 | C16: South East | D16: Facilities Response | E16: Supplier delay | F16: Low | G16: Closed | H16: 2.7 | I16: 20.4 | J16: Documentation updated
A17: INC-00016 | B17: 46181 | C17: North West | D17: Workplace Services | E17: Health & safety issue | F17: Low | G17: In Progress | H17: 3.1 | I17: 11.5
A18: INC-00017 | B18: 46090 | C18: South East | D18: Facilities Response | E18: Staffing shortage | F18: Low | G18: Closed | H18: 3.3 | I18: 19.2 | J18: Supplier action
A19: INC-00018 | B19: 46091 | C19: South East | D19: Facilities Response | E19: Process failure | F19: High | G19: Closed | H19: 25.9 | I19: 31 | J19: Documentation updated
A20: INC-00019 | B20: 46126 | C20: Midlands | D20: Workplace Services | E20: Health & safety issue | F20: Low | G20: Open | H20: 3.5 | I20: 4.9
A21: INC-00020 | B21: 46090 | C21: South East | D21: Workplace Services | E21: Supplier delay | F21: Medium | G21: Closed | H21: 4.8 | I21: 21.6 | J21: Supplier action
A22: INC-00021 | B22: 46051 | C22: Scotland | D22: Workplace Services | E22: Customer escalation | F22: High | G22: Closed | H22: 1.9 | I22: 130.1 | J22: No further action
A23: INC-00022 | B23: 46079 | C23: North West | D23: Facilities Response | E23: Health & safety issue | F23: Medium | G23: In Progress | H23: 2.9 | I23: 27.4
A24: INC-00023 | B24: 46202 | C24: South East | D24: Facilities Response | E24: Customer escalation | F24: Low | G24: Open | H24: 3 | I24: 34.8
A25: INC-00024 | B25: 46152 | C25: Midlands | D25: Estates Support | E25: System outage | F25: Medium | G25: Closed | H25: 0.7 | I25: 44.6 | J25: Process updated
A26: INC-00025 | B26: 46202 | C26: North West | D26: Workplace Projects | E26: Building issue | F26: Low | G26: Closed | H26: 3.9 | I26: 4.1 | J26: Documentation updated
A27: INC-00026 | B27: 46071 | C27: North East | D27: Workplace Projects | E27: Data quality issue | F27: Medium | G27: Open | H27: 4.3 | I27: 8
A28: INC-00027 | B28: 46093 | C28: South West | D28: Workplace Services | E28: Staffing shortage | F28: Low | G28: Closed | H28: 6 | I28: 11.4 | J28: Documentation updated
A29: INC-00028 | B29: 46071 | C29: North West | D29: Facilities Response | E29: Staffing shortage | F29: High | G29: Closed | H29: 3.8 | I29: 42.1 | J29: Training required
A30: INC-00029 | B30: 46135 | C30: North West | D30: Facilities Response | E30: Data quality issue | F30: Medium | G30: Closed | H30: 2.5 | I30: 3.9 | J30: Supplier action
A31: INC-00030 | B31: 46054 | C31: North West | D31: Estates Support | E31: Data quality issue | F31: Medium | G31: Closed | H31: 0.6 | I31: 3.7 | J31: Training required
A32: INC-00031 | B32: 46157 | C32: South West | D32: Workplace Services | E32: Staffing shortage | F32: Medium | G32: Closed | H32: 4 | I32: 20.3 | J32: Process updated
A33: INC-00032 | B33: 46089 | C33: South East | D33: Workplace Projects | E33: Supplier delay | F33: Low | G33: Closed | H33: 1.3 | I33: 17.4 | J33: Supplier action
A34: INC-00033 | B34: 46166 | C34: North West | D34: Workplace Services | E34: Process failure | F34: Low | G34: Closed | H34: 0.4 | I34: 1.5 | J34: Documentation updated
A35: INC-00034 | B35: 46169 | C35: Scotland | D35: Estates Support | E35: Data quality issue | F35: Medium | G35: Closed | H35: 11.7 | I35: 42.3 | J35: No further action
A36: INC-00035 | B36: 46033 | C36: North East | D36: Facilities Response | E36: Customer escalation | F36: Low | G36: Open | H36: 6.6 | I36: 11.9
A37: INC-00036 | B37: 46159 | C37: Midlands | D37: Workplace Projects | E37: Supplier delay | F37: Low | G37: Open | H37: 0.9 | I37: 26.5
A38: INC-00037 | B38: 46142 | C38: Wales | D38: Estates Support | E38: System outage | F38: Medium | G38: Closed | H38: 0.6 | I38: 6.2 | J38: Training required
A39: INC-00038 | B39: 46047 | C39: North East | D39: Facilities Response | E39: Process failure | F39: Medium | G39: Open | H39: 1.2 | I39: 42.7
A40: INC-00039 | B40: 46120 | C40: North West | D40: Estates Support | E40: Health & safety issue | F40: High | G40: In Progress | H40: 15.2 | I40: 36.3
...

Sheet 04_References
A1: KPI_Name | B1: Source_Field | C1: Target_Value | D1: Target_Description
A2: Completion Rate | B2: Completion_Rate | C2: 0.95 | D2: Minimum 95% of available workload completed
A3: SLA Compliance | B3: SLA_Compliance | C3: 0.92 | D3: Target percentage completed within SLA
A4: Quality Pass Rate | B4: Quality_Pass_Rate | C4: 0.95 | D4: Target percentage passing quality checks
A5: Customer Satisfaction | B5: Customer_Satisfaction | C5: 4.2 | D5: Target average customer satisfaction score
A6: Staff Utilisation | B6: Staff_Utilisation | C6: 0.75 | D6: Target productive utilisation
A7: Average Completion Days | B7: Average_Completion_Days | C7: 3 | D7: Maximum preferred average completion time
A8: Closing Backlog | B8: Closing_Backlog | C8: 10 | D8: Preferred maximum daily closing backlog
D17: =">"&'04_References'!B4&"<" -> >Quality_Pass_Rate<
D18: =LEN('04_References'!B4) -> 17

Sheet 05_regional
A1: Region | B1: Area | C1: Primary_Office | D1: Regional_Lead
A2: Scotland | B2: North | C2: Edinburgh | D2: Regional Lead A
A3: North East | B3: North | C3: Newcastle | D3: Regional Lead B
A4: North West | B4: North | C4: Manchester | D4: Regional Lead C
A5: Midlands | B5: Central | C5: Birmingham | D5: Regional Lead D
A6: South West | B6: South | C6: Bristol | D6: Regional Lead E
A7: South East | B7: South | C7: Worthing | D7: Regional Lead F
A8: Wales | B8: Wales | C8: Cardiff | D8: Regional Lead G

Sheet 06_Clean_Operations
A1: Record_ID | B1: Date | C1: Region | D1: Team | E1: Opening_Backlog | F1: Requests_Received | G1: Total_Workload | H1: Requests_Completed | I1: Closing_Backlog | J1: Incident_Count | K1: High_Critical_Incidents | L1: Average_Completion_Days | M1: SLA_Compliance | N1: Quality_Pass_Rate | O1: Customer_Satisfaction | P1: Staff_Utilisation | Q1: Completion_Rate | R1: Clean_Region | S1: Clean_Team | T1: Area | U1: Completion_Status | V1: SLA_Status | W1: Quality_Status | X1: Average_Completion_Days_Status | Y1: Closing_Backlog_Status
A2: OPS-100001 | B2: 46023 | C2: Scotland | D2: Workplace Services | E2: 9 | F2: 55 | G2: 64 | H2: 34 | I2: 30 | J2: 0 | K2: 0 | L2: 4.3 | M2: 0.789 | N2: 0.951 | O2: 3.5 | P2: 0.705 | Q2: 0.531 | R2: =TRIM(tblOperations[[#This Row],[Region]]) -> Scotland | S2: =TRIM(tblOperations[[#This Row],[Team]]) -> Workplace Services | T2: =_xlfn.XLOOKUP(R2,tblRegionReference[Region],tblRegionReference[Area],"Not Found") -> North | U2: =IF(tblOperations[[#This Row],[Completion_Rate]]>=_xlfn.XLOOKUP("Completion Rate",tblKPITargets[KPI_Name],tblKPITargets[Target_Value]),"Met","Below Target") -> Below Target | V2: =IF(tblOperations[[#This Row],[SLA_Compliance]]>=_xlfn.XLOOKUP('04_References'!$A$3,tblKPITargets[KPI_Name],tblKPITargets[Target_Value]),"Met","Below Target") -> Below Target | W2: =IF(tblOperations[[#This Row],[Quality_Pass_Rate]]>=_xlfn.XLOOKUP('04_References'!$A$4,tblKPITargets[KPI_Name],tblKPITargets[Target_Value]),"Met","Below Target") -> Met | X2: =IF(tblOperations[[#This Row],[Average_Completion_Days]]<=_xlfn.XLOOKUP('04_References'!$A$7,tblKPITargets[KPI_Name],tblKPITargets[Target_Value]),"Met","Below Target") -> Below Target | Y2: =IF(tblOperations[[#This Row],[Closing_Backlog]]<=_xlfn.XLOOKUP('04_References'!$A$8,tblKPITargets[KPI_Name],tblKPITargets[Target_Value]),"Met","Below Target") -> Below Target
A3: OPS-100002 | B3: 46023 | C3: Scotland | D3: Facilities Response | E3: 8 | F3: 51 | G3: 59 | H3: 57 | I3: 2 | J3: 0 | K3: 0 | L3: 2.1 | M3: 0.995 | N3: 0.992 | O3: 4.4 | P3: 0.71 | Q3: 0.966 | R3: =TRIM(tblOperations[[#This Row],[Region]]) -> Scotland | S3: =TRIM(tblOperations[[#This Row],[Team]]) -> Facilities Response | T3: =_xlfn.XLOOKUP(R3,tblRegionReference[Region],tblRegionReference[Area],"Not Found") -> North | U3: =IF(tblOperations[[#This Row],[Completion_Rate]]>=_xlfn.XLOOKUP("Completion Rate",tblKPITargets[KPI_Name],tblKPITargets[Target_Value]),"Met","Below Target") -> Met | V3: =IF(tblOperations[[#This Row],[SLA_Compliance]]>=_xlfn.XLOOKUP('04_References'!$A$3,tblKPITargets[KPI_Name],tblKPITargets[Target_Value]),"Met","Below Target") -> Met | W3: =IF(tblOperations[[#This Row],[Quality_Pass_Rate]]>=_xlfn.XLOOKUP('04_References'!$A$4,tblKPITargets[KPI_Name],tblKPITargets[Target_Value]),"Met","Below Target") -> Met | X3: =IF(tblOperations[[#This Row],[Average_Completion_Days]]<=_xlfn.XLOOKUP('04_References'!$A$7,tblKPITargets[KPI_Name],tblKPITargets[Target_Value]),"Met","Below Target") -> Met | Y3: =IF(tblOperations[[#This Row],[Closing_Backlog]]<=_xlfn.XLOOKUP('04_References'!$A$8,tblKPITargets[KPI_Name],tblKPITargets[Target_Value]),"Met","Below Target") -> Met
A4: OPS-100003 | B4: 46023 | C4: Scotland | D4: Estates Support | E4: 11 | F4: 62 | G4: 73 | H4: 39 | I4: 34 | J4: 0 | K4: 0 | L4: 4.3 | M4: 0.719 | N4: 0.973 | O4: 3.4 | P4: 0.786 | Q4: 0.534 | R4: =TRIM(tblOperations[[#This Row],[Region]]) -> Scotland | S4: =TRIM(tblOperations[[#This Row],[Team]]) -> Estates Support | T4: =_xlfn.XLOOKUP(R4,tblRegionReference[Region],tblRegionReference[Area],"Not Found") -> North | U4: =IF(tblOperations[[#This Row],[Completion_Rate]]>=_xlfn.XLOOKUP("Completion Rate",tblKPITargets[KPI_Name],tblKPITargets[Target_Value]),"Met","Below Target") -> Below Target | V4: =IF(tblOperations[[#This Row],[SLA_Compliance]]>=_xlfn.XLOOKUP('04_References'!$A$3,tblKPITargets[KPI_Name],tblKPITargets[Target_Value]),"Met","Below Target") -> Below Target | W4: =IF(tblOperations[[#This Row],[Quality_Pass_Rate]]>=_xlfn.XLOOKUP('04_References'!$A$4,tblKPITargets[KPI_Name],tblKPITargets[Target_Value]),"Met","Below Target") -> Met | X4: =IF(tblOperations[[#This Row],[Average_Completion_Days]]<=_xlfn.XLOOKUP('04_References'!$A$7,tblKPITargets[KPI_Name],tblKPITargets[Target_Value]),"Met","Below Target") -> Below Target | Y4: =IF(tblOperations[[#This Row],[Closing_Backlog]]<=_xlfn.XLOOKUP('04_References'!$A$8,tblKPITargets[KPI_Name],tblKPITargets[Target_Value]),"Met","Below Target") -> Below Target
A5: OPS-100004 | B5: 46023 | C5: Scotland | D5: Workplace Projects | E5: 12 | F5: 35 | G5: 47 | H5: 46 | I5: 1 | J5: 0 | K5: 0 | L5: 1.2 | M5: 0.972 | N5: 0.996 | O5: 4.4 | P5: 0.777 | Q5: 0.979 | R5: =TRIM(tblOperations[[#This Row],[Region]]) -> Scotland | S5: =TRIM(tblOperations[[#This Row],[Team]]) -> Workplace Projects | T5: =_xlfn.XLOOKUP(R5,tblRegionReference[Region],tblRegionReference[Area],"Not Found") -> North | U5: =IF(tblOperations[[#This Row],[Completion_Rate]]>=_xlfn.XLOOKUP("Completion Rate",tblKPITargets[KPI_Name],tblKPITargets[Target_Value]),"Met","Below Target") -> Met | V5: =IF(tblOperations[[#This Row],[SLA_Compliance]]>=_xlfn.XLOOKUP('04_References'!$A$3,tblKPITargets[KPI_Name],tblKPITargets[Target_Value]),"Met","Below Target") -> Met | W5: =IF(tblOperations[[#This Row],[Quality_Pass_Rate]]>=_xlfn.XLOOKUP('04_References'!$A$4,tblKPITargets[KPI_Name],tblKPITargets[Target_Value]),"Met","Below Target") -> Met | X5: =IF(tblOperations[[#This Row],[Average_Completion_Days]]<=_xlfn.XLOOKUP('04_References'!$A$7,tblKPITargets[KPI_Name],tblKPITargets[Target_Value]),"Met","Below Target") -> Met | Y5: =IF(tblOperations[[#This Row],[Closing_Backlog]]<=_xlfn.XLOOKUP('04_References'!$A$8,tblKPITargets[KPI_Name],tblKPITargets[Target_Value]),"Met","Below Target") -> Met
A6: OPS-100005 | B6: 46023 | C6: North East | D6: Workplace Services | E6: 12 | F6: 49 | G6: 61 | H6: 44 | I6: 17 | J6: 0 | K6: 0 | L6: 2.9 | M6: 0.848 | N6: 0.967 | O6: 3.9 | P6: 0.692 | Q6: 0.721 | R6: =TRIM(tblOperations[[#This Row],[Region]]) -> North East | S6: =TRIM(tblOperations[[#This Row],[Team]]) -> Workplace Services | T6: =_xlfn.XLOOKUP(R6,tblRegionReference[Region],tblRegionReference[Area],"Not Found") -> North | U6: =IF(tblOperations[[#This Row],[Completion_Rate]]>=_xlfn.XLOOKUP("Completion Rate",tblKPITargets[KPI_Name],tblKPITargets[Target_Value]),"Met","Below Target") -> Below Target | V6: =IF(tblOperations[[#This Row],[SLA_Compliance]]>=_xlfn.XLOOKUP('04_References'!$A$3,tblKPITargets[KPI_Name],tblKPITargets[Target_Value]),"Met","Below Target") -> Below Target | W6: =IF(tblOperations[[#This Row],[Quality_Pass_Rate]]>=_xlfn.XLOOKUP('04_References'!$A$4,tblKPITargets[KPI_Name],tblKPITargets[Target_Value]),"Met","Below Target") -> Met | X6: =IF(tblOperations[[#This Row],[Average_Completion_Days]]<=_xlfn.XLOOKUP('04_References'!$A$7,tblKPITargets[KPI_Name],tblKPITargets[Target_Value]),"Met","Below Target") -> Met | Y6: =IF(tblOperations[[#This Row],[Closing_Backlog]]<=_xlfn.XLOOKUP('04_References'!$A$8,tblKPITargets[KPI_Name],tblKPITargets[Target_Value]),"Met","Below Target") -> Below Target
A7: OPS-100006 | B7: 46023 | C7: North East | D7: Facilities Response | E7: 12 | F7: 26 | G7: 38 | H7: 38 | I7: 0 | J7: 0 | K7: 0 | L7: 1.4 | M7: 0.95 | N7: 1 | O7: 4.8 | P7: 0.706 | Q7: 1 | R7: =TRIM(tblOperations[[#This Row],[Region]]) -> North East | S7: =TRIM(tblOperations[[#This Row],[Team]]) -> Facilities Response | T7: =_xlfn.XLOOKUP(R7,tblRegionReference[Region],tblRegionReference[Area],"Not Found") -> North | U7: =IF(tblOperations[[#This Row],[Completion_Rate]]>=_xlfn.XLOOKUP("Completion Rate",tblKPITargets[KPI_Name],tblKPITargets[Target_Value]),"Met","Below Target") -> Met | V7: =IF(tblOperations[[#This Row],[SLA_Compliance]]>=_xlfn.XLOOKUP('04_References'!$A$3,tblKPITargets[KPI_Name],tblKPITargets[Target_Value]),"Met","Below Target") -> Met | W7: =IF(tblOperations[[#This Row],[Quality_Pass_Rate]]>=_xlfn.XLOOKUP('04_References'!$A$4,tblKPITargets[KPI_Name],tblKPITargets[Target_Value]),"Met","Below Target") -> Met | X7: =IF(tblOperations[[#This Row],[Average_Completion_Days]]<=_xlfn.XLOOKUP('04_References'!$A$7,tblKPITargets[KPI_Name],tblKPITargets[Target_Value]),"Met","Below Target") -> Met | Y7: =IF(tblOperations[[#This Row],[Closing_Backlog]]<=_xlfn.XLOOKUP('04_References'!$A$8,tblKPITargets[KPI_Name],tblKPITargets[Target_Value]),"Met","Below Target") -> Met
A8: OPS-100007 | B8: 46023 | C8: North East | D8: Estates Support | E8: 12 | F8: 30 | G8: 42 | H8: 17 | I8: 25 | J8: 0 | K8: 0 | L8: 4 | M8: 0.856 | N8: 0.981 | O8: 3.4 | P8: 0.709 | Q8: 0.405 | R8: =TRIM(tblOperations[[#This Row],[Region]]) -> North East | S8: =TRIM(tblOperations[[#This Row],[Team]]) -> Estates Support | T8: =_xlfn.XLOOKUP(R8,tblRegionReference[Region],tblRegionReference[Area],"Not Found") -> North | U8: =IF(tblOperations[[#This Row],[Completion_Rate]]>=_xlfn.XLOOKUP("Completion Rate",tblKPITargets[KPI_Name],tblKPITargets[Target_Value]),"Met","Below Target") -> Below Target | V8: =IF(tblOperations[[#This Row],[SLA_Compliance]]>=_xlfn.XLOOKUP('04_References'!$A$3,tblKPITargets[KPI_Name],tblKPITargets[Target_Value]),"Met","Below Target") -> Below Target | W8: =IF(tblOperations[[#This Row],[Quality_Pass_Rate]]>=_xlfn.XLOOKUP('04_References'!$A$4,tblKPITargets[KPI_Name],tblKPITargets[Target_Value]),"Met","Below Target") -> Met | X8: =IF(tblOperations[[#This Row],[Average_Completion_Days]]<=_xlfn.XLOOKUP('04_References'!$A$7,tblKPITargets[KPI_Name],tblKPITargets[Target_Value]),"Met","Below Target") -> Below Target | Y8: =IF(tblOperations[[#This Row],[Closing_Backlog]]<=_xlfn.XLOOKUP('04_References'!$A$8,tblKPITargets[KPI_Name],tblKPITargets[Target_Value]),"Met","Below Target") -> Below Target
A9: OPS-100008 | B9: 46023 | C9: North East | D9: Workplace Projects | E9: 11 | F9: 27 | G9: 38 | H9: 28 | I9: 10 | J9: 0 | K9: 0 | L9: 2.2 | M9: 0.928 | N9: 0.979 | O9: 4.5 | P9: 0.774 | Q9: 0.737 | R9: =TRIM(tblOperations[[#This Row],[Region]]) -> North East | S9: =TRIM(tblOperations[[#This Row],[Team]]) -> Workplace Projects | T9: =_xlfn.XLOOKUP(R9,tblRegionReference[Region],tblRegionReference[Area],"Not Found") -> North | U9: =IF(tblOperations[[#This Row],[Completion_Rate]]>=_xlfn.XLOOKUP("Completion Rate",tblKPITargets[KPI_Name],tblKPITargets[Target_Value]),"Met","Below Target") -> Below Target | V9: =IF(tblOperations[[#This Row],[SLA_Compliance]]>=_xlfn.XLOOKUP('04_References'!$A$3,tblKPITargets[KPI_Name],tblKPITargets[Target_Value]),"Met","Below Target") -> Met | W9: =IF(tblOperations[[#This Row],[Quality_Pass_Rate]]>=_xlfn.XLOOKUP('04_References'!$A$4,tblKPITargets[KPI_Name],tblKPITargets[Target_Value]),"Met","Below Target") -> Met | X9: =IF(tblOperations[[#This Row],[Average_Completion_Days]]<=_xlfn.XLOOKUP('04_References'!$A$7,tblKPITargets[KPI_Name],tblKPITargets[Target_Value]),"Met","Below Target") -> Met | Y9: =IF(tblOperations[[#This Row],[Closing_Backlog]]<=_xlfn.XLOOKUP('04_References'!$A$8,tblKPITargets[KPI_Name],tblKPITargets[Target_Value]),"Met","Below Target") -> Met
A10: OPS-100009 | B10: 46023 | C10: North West | D10: Workplace Services | E10: 9 | F10: 42 | G10: 51 | H10: 36 | I10: 15 | J10: 0 | K10: 0 | L10: 2.6 | M10: 0.86 | N10: 1 | O10: 4.1 | P10: 0.779 | Q10: 0.706 | R10: =TRIM(tblOperations[[#This Row],[Region]]) -> North West | S10: =TRIM(tblOperations[[#This Row],[Team]]) -> Workplace Services | T10: =_xlfn.XLOOKUP(R10,tblRegionReference[Region],tblRegionReference[Area],"Not Found") -> North | U10: =IF(tblOperations[[#This Row],[Completion_Rate]]>=_xlfn.XLOOKUP("Completion Rate",tblKPITargets[KPI_Name],tblKPITargets[Target_Value]),"Met","Below Target") -> Below Target | V10: =IF(tblOperations[[#This Row],[SLA_Compliance]]>=_xlfn.XLOOKUP('04_References'!$A$3,tblKPITargets[KPI_Name],tblKPITargets[Target_Value]),"Met","Below Target") -> Below Target | W10: =IF(tblOperations[[#This Row],[Quality_Pass_Rate]]>=_xlfn.XLOOKUP('04_References'!$A$4,tblKPITargets[KPI_Name],tblKPITargets[Target_Value]),"Met","Below Target") -> Met | X10: =IF(tblOperations[[#This Row],[Average_Completion_Days]]<=_xlfn.XLOOKUP('04_References'!$A$7,tblKPITargets[KPI_Name],tblKPITargets[Target_Value]),"Met","Below Target") -> Met | Y10: =IF(tblOperations[[#This Row],[Closing_Backlog]]<=_xlfn.XLOOKUP('04_References'!$A$8,tblKPITargets[KPI_Name],tblKPITargets[Target_Value]),"Met","Below Target") -> Below Target
A11: OPS-100010 | B11: 46023 | C11: North West | D11: Facilities Response | E11: 6 | F11: 46 | G11: 52 | H11: 27 | I11: 25 | J11: 0 | K11: 0 | L11: 3.8 | M11: 0.814 | N11: 1 | O11: 3.6 | P11: 0.783 | Q11: 0.519 | R11: =TRIM(tblOperations[[#This Row],[Region]]) -> North West | S11: =TRIM(tblOperations[[#This Row],[Team]]) -> Facilities Response | T11: =_xlfn.XLOOKUP(R11,tblRegionReference[Region],tblRegionReference[Area],"Not Found") -> North | U11: =IF(tblOperations[[#This Row],[Completion_Rate]]>=_xlfn.XLOOKUP("Completion Rate",tblKPITargets[KPI_Name],tblKPITargets[Target_Value]),"Met","Below Target") -> Below Target | V11: =IF(tblOperations[[#This Row],[SLA_Compliance]]>=_xlfn.XLOOKUP('04_References'!$A$3,tblKPITargets[KPI_Name],tblKPITargets[Target_Value]),"Met","Below Target") -> Below Target | W11: =IF(tblOperations[[#This Row],[Quality_Pass_Rate]]>=_xlfn.XLOOKUP('04_References'!$A$4,tblKPITargets[KPI_Name],tblKPITargets[Target_Value]),"Met","Below Target") -> Met | X11: =IF(tblOperations[[#This Row],[Average_Completion_Days]]<=_xlfn.XLOOKUP('04_References'!$A$7,tblKPITargets[KPI_Name],tblKPITargets[Target_Value]),"Met","Below Target") -> Below Target | Y11: =IF(tblOperations[[#This Row],[Closing_Backlog]]<=_xlfn.XLOOKUP('04_References'!$A$8,tblKPITargets[KPI_Name],tblKPITargets[Target_Value]),"Met","Below Target") -> Below Target
A12: OPS-100011 | B12: 46023 | C12: North West | D12: Estates Support | E12: 5 | F12: 44 | G12: 49 | H12: 17 | I12: 32 | J12: 1 | K12: 0 | L12: 3.9 | M12: 0.725 | N12: 0.97 | O12: 3.1 | P12: 0.667 | Q12: 0.347 | R12: =TRIM(tblOperations[[#This Row],[Region]]) -> North West | S12: =TRIM(tblOperations[[#This Row],[Team]]) -> Estates Support | T12: =_xlfn.XLOOKUP(R12,tblRegionReference[Region],tblRegionReference[Area],"Not Found") -> North | U12: =IF(tblOperations[[#This Row],[Completion_Rate]]>=_xlfn.XLOOKUP("Completion Rate",tblKPITargets[KPI_Name],tblKPITargets[Target_Value]),"Met","Below Target") -> Below Target | V12: =IF(tblOperations[[#This Row],[SLA_Compliance]]>=_xlfn.XLOOKUP('04_References'!$A$3,tblKPITargets[KPI_Name],tblKPITargets[Target_Value]),"Met","Below Target") -> Below Target | W12: =IF(tblOperations[[#This Row],[Quality_Pass_Rate]]>=_xlfn.XLOOKUP('04_References'!$A$4,tblKPITargets[KPI_Name],tblKPITargets[Target_Value]),"Met","Below Target") -> Met | X12: =IF(tblOperations[[#This Row],[Average_Completion_Days]]<=_xlfn.XLOOKUP('04_References'!$A$7,tblKPITargets[KPI_Name],tblKPITargets[Target_Value]),"Met","Below Target") -> Below Target | Y12: =IF(tblOperations[[#This Row],[Closing_Backlog]]<=_xlfn.XLOOKUP('04_References'!$A$8,tblKPITargets[KPI_Name],tblKPITargets[Target_Value]),"Met","Below Target") -> Below Target
A13: OPS-100012 | B13: 46023 | C13: North West | D13: Workplace Projects | E13: 14 | F13: 36 | G13: 50 | H13: 47 | I13: 3 | J13: 0 | K13: 0 | L13: 2.1 | M13: 0.957 | N13: 0.964 | O13: 4.3 | P13: 0.723 | Q13: 0.94 | R13: =TRIM(tblOperations[[#This Row],[Region]]) -> North West | S13: =TRIM(tblOperations[[#This Row],[Team]]) -> Workplace Projects | T13: =_xlfn.XLOOKUP(R13,tblRegionReference[Region],tblRegionReference[Area],"Not Found") -> North | U13: =IF(tblOperations[[#This Row],[Completion_Rate]]>=_xlfn.XLOOKUP("Completion Rate",tblKPITargets[KPI_Name],tblKPITargets[Target_Value]),"Met","Below Target") -> Below Target | V13: =IF(tblOperations[[#This Row],[SLA_Compliance]]>=_xlfn.XLOOKUP('04_References'!$A$3,tblKPITargets[KPI_Name],tblKPITargets[Target_Value]),"Met","Below Target") -> Met | W13: =IF(tblOperations[[#This Row],[Quality_Pass_Rate]]>=_xlfn.XLOOKUP('04_References'!$A$4,tblKPITargets[KPI_Name],tblKPITargets[Target_Value]),"Met","Below Target") -> Met | X13: =IF(tblOperations[[#This Row],[Average_Completion_Days]]<=_xlfn.XLOOKUP('04_References'!$A$7,tblKPITargets[KPI_Name],tblKPITargets[Target_Value]),"Met","Below Target") -> Met | Y13: =IF(tblOperations[[#This Row],[Closing_Backlog]]<=_xlfn.XLOOKUP('04_References'!$A$8,tblKPITargets[KPI_Name],tblKPITargets[Target_Value]),"Met","Below Target") -> Met
... A351: OPS-100350 | B351: 46037 | C351: Midlands | D351: Facilities Response | E351: 150 | F351: 47 | G351: 197 | H351: 30 | I351: 167 | J351: 0 | K351: 0 | L351: 8 | M351: 0.6 | N351: 0.983 | O351: 2.5 | P351: 0.788 | Q351: 0.152 | R351: =TRIM(tblOperations[[#This Row],[Region]]) -> Midlands | S351: =TRIM(tblOperations[[#This Row],[Team]]) -> Facilities Response | T351: =_xlfn.XLOOKUP(R351,tblRegionReference[Region],tblRegionReference[Area],"Not Found") -> Central | U351: =IF(tblOperations[[#This Row],[Completion_Rate]]>=_xlfn.XLOOKUP("Completion Rate",tblKPITargets[KPI_Name],tblKPITargets[Target_Value]),"Met","Below Target") -> Below Target | V351: =IF(tblOperations[[#This Row],[SLA_Compliance]]>=_xlfn.XLOOKUP('04_References'!$A$3,tblKPITargets[KPI_Name],tblKPITargets[Target_Value]),"Met","Below Target") -> Below Target | W351: =IF(tblOperations[[#This Row],[Quality_Pass_Rate]]>=_xlfn.XLOOKUP('04_References'!$A$4,tblKPITargets[KPI_Name],tblKPITargets[Target_Value]),"Met","Below Target") -> Met | X351: =IF(tblOperations[[#This Row],[Average_Completion_Days]]<=_xlfn.XLOOKUP('04_References'!$A$7,tblKPITargets[KPI_Name],tblKPITargets[Target_Value]),"Met","Below Target") -> Below Target | Y351: =IF(tblOperations[[#This Row],[Closing_Backlog]]<=_xlfn.XLOOKUP('04_References'!$A$8,tblKPITargets[KPI_Name],tblKPITargets[Target_Value]),"Met","Below Target") -> Below Target
A352: OPS-100351 | B352: 46037 | C352: Midlands | D352: Estates Support | E352: 75 | F352: 34 | G352: 109 | H352: 36 | I352: 73 | J352: 0 | K352: 0 | L352: 7.2 | M352: 0.6 | N352: 0.979 | P352: 0.788 | Q352: 0.33 | R352: =TRIM(tblOperations[[#This Row],[Region]]) -> Midlands | S352: =TRIM(tblOperations[[#This Row],[Team]]) -> Estates Support | T352: =_xlfn.XLOOKUP(R352,tblRegionReference[Region],tblRegionReference[Area],"Not Found") -> Central | U352: =IF(tblOperations[[#This Row],[Completion_Rate]]>=_xlfn.XLOOKUP("Completion Rate",tblKPITargets[KPI_Name],tblKPITargets[Target_Value]),"Met","Below Target") -> Below Target | V352: =IF(tblOperations[[#This Row],[SLA_Compliance]]>=_xlfn.XLOOKUP('04_References'!$A$3,tblKPITargets[KPI_Name],tblKPITargets[Target_Value]),"Met","Below Target") -> Below Target | W352: =IF(tblOperations[[#This Row],[Quality_Pass_Rate]]>=_xlfn.XLOOKUP('04_References'!$A$4,tblKPITargets[KPI_Name],tblKPITargets[Target_Value]),"Met","Below Target") -> Met | X352: =IF(tblOperations[[#This Row],[Average_Completion_Days]]<=_xlfn.XLOOKUP('04_References'!$A$7,tblKPITargets[KPI_Name],tblKPITargets[Target_Value]),"Met","Below Target") -> Below Target | Y352: =IF(tblOperations[[#This Row],[Closing_Backlog]]<=_xlfn.XLOOKUP('04_References'!$A$8,tblKPITargets[KPI_Name],tblKPITargets[Target_Value]),"Met","Below Target") -> Below Target
A353: OPS-100352 | B353: 46037 | C353: Midlands | D353: Workplace Projects | E353: 0 | F353: 34 | G353: 34 | H353: 34 | I353: 0 | J353: 0 | K353: 0 | L353: 1.8 | M353: 0.989 | N353: 1 | O353: 4.7 | P353: 0.72 | Q353: 1 | R353: =TRIM(tblOperations[[#This Row],[Region]]) -> Midlands | S353: =TRIM(tblOperations[[#This Row],[Team]]) -> Workplace Projects | T353: =_xlfn.XLOOKUP(R353,tblRegionReference[Region],tblRegionReference[Area],"Not Found") -> Central | U353: =IF(tblOperations[[#This Row],[Completion_Rate]]>=_xlfn.XLOOKUP("Completion Rate",tblKPITargets[KPI_Name],tblKPITargets[Target_Value]),"Met","Below Target") -> Met | V353: =IF(tblOperations[[#This Row],[SLA_Compliance]]>=_xlfn.XLOOKUP('04_References'!$A$3,tblKPITargets[KPI_Name],tblKPITargets[Target_Value]),"Met","Below Target") -> Met | W353: =IF(tblOperations[[#This Row],[Quality_Pass_Rate]]>=_xlfn.XLOOKUP('04_References'!$A$4,tblKPITargets[KPI_Name],tblKPITargets[Target_Value]),"Met","Below Target") -> Met | X353: =IF(tblOperations[[#This Row],[Average_Completion_Days]]<=_xlfn.XLOOKUP('04_References'!$A$7,tblKPITargets[KPI_Name],tblKPITargets[Target_Value]),"Met","Below Target") -> Met | Y353: =IF(tblOperations[[#This Row],[Closing_Backlog]]<=_xlfn.XLOOKUP('04_References'!$A$8,tblKPITargets[KPI_Name],tblKPITargets[Target_Value]),"Met","Below Target") -> Met
A354: OPS-100353 | B354: 46037 | C354: South West | D354: Workplace Services | E354: 174 | F354: 54 | G354: 228 | H354: 25 | I354: 203 | J354: 0 | K354: 0 | L354: 8 | M354: 0.6 | N354: 0.993 | O354: 2.5 | P354: 0.703 | Q354: 0.11 | R354: =TRIM(tblOperations[[#This Row],[Region]]) -> South West | S354: =TRIM(tblOperations[[#This Row],[Team]]) -> Workplace Services | T354: =_xlfn.XLOOKUP(R354,tblRegionReference[Region],tblRegionReference[Area],"Not Found") -> South | U354: =IF(tblOperations[[#This Row],[Completion_Rate]]>=_xlfn.XLOOKUP("Completion Rate",tblKPITargets[KPI_Name],tblKPITargets[Target_Value]),"Met","Below Target") -> Below Target | V354: =IF(tblOperations[[#This Row],[SLA_Compliance]]>=_xlfn.XLOOKUP('04_References'!$A$3,tblKPITargets[KPI_Name],tblKPITargets[Target_Value]),"Met","Below Target") -> Below Target | W354: =IF(tblOperations[[#This Row],[Quality_Pass_Rate]]>=_xlfn.XLOOKUP('04_References'!$A$4,tblKPITargets[KPI_Name],tblKPITargets[Target_Value]),"Met","Below Target") -> Met | X354: =IF(tblOperations[[#This Row],[Average_Completion_Days]]<=_xlfn.XLOOKUP('04_References'!$A$7,tblKPITargets[KPI_Name],tblKPITargets[Target_Value]),"Met","Below Target") -> Below Target | Y354: =IF(tblOperations[[#This Row],[Closing_Backlog]]<=_xlfn.XLOOKUP('04_References'!$A$8,tblKPITargets[KPI_Name],tblKPITargets[Target_Value]),"Met","Below Target") -> Below Target
A355: OPS-100354 | B355: 46037 | C355: South West | D355: Facilities Response | E355: 0 | F355: 39 | G355: 39 | H355: 39 | I355: 0 | J355: 0 | K355: 0 | L355: 1.1 | M355: 1 | N355: 0.977 | O355: 4.8 | P355: 0.689 | Q355: 1 | R355: =TRIM(tblOperations[[#This Row],[Region]]) -> South West | S355: =TRIM(tblOperations[[#This Row],[Team]]) -> Facilities Response | T355: =_xlfn.XLOOKUP(R355,tblRegionReference[Region],tblRegionReference[Area],"Not Found") -> South | U355: =IF(tblOperations[[#This Row],[Completion_Rate]]>=_xlfn.XLOOKUP("Completion Rate",tblKPITargets[KPI_Name],tblKPITargets[Target_Value]),"Met","Below Target") -> Met | V355: =IF(tblOperations[[#This Row],[SLA_Compliance]]>=_xlfn.XLOOKUP('04_References'!$A$3,tblKPITargets[KPI_Name],tblKPITargets[Target_Value]),"Met","Below Target") -> Met | W355: =IF(tblOperations[[#This Row],[Quality_Pass_Rate]]>=_xlfn.XLOOKUP('04_References'!$A$4,tblKPITargets[KPI_Name],tblKPITargets[Target_Value]),"Met","Below Target") -> Met | X355: =IF(tblOperations[[#This Row],[Average_Completion_Days]]<=_xlfn.XLOOKUP('04_References'!$A$7,tblKPITargets[KPI_Name],tblKPITargets[Target_Value]),"Met","Below Target") -> Met | Y355: =IF(tblOperations[[#This Row],[Closing_Backlog]]<=_xlfn.XLOOKUP('04_References'!$A$8,tblKPITargets[KPI_Name],tblKPITargets[Target_Value]),"Met","Below Target") -> Met
A356: OPS-100355 | B356: 46037 | C356: South West | D356: Estates Support | E356: 16 | F356: 32 | G356: 48 | H356: 48 | I356: 0 | J356: 0 | K356: 0 | L356: 1.7 | M356: 0.976 | N356: 0.959 | O356: 4.6 | P356: 0.649 | Q356: 1 | R356: =TRIM(tblOperations[[#This Row],[Region]]) -> South West | S356: =TRIM(tblOperations[[#This Row],[Team]]) -> Estates Support | T356: =_xlfn.XLOOKUP(R356,tblRegionReference[Region],tblRegionReference[Area],"Not Found") -> South | U356: =IF(tblOperations[[#This Row],[Completion_Rate]]>=_xlfn.XLOOKUP("Completion Rate",tblKPITargets[KPI_Name],tblKPITargets[Target_Value]),"Met","Below Target") -> Met | V356: =IF(tblOperations[[#This Row],[SLA_Compliance]]>=_xlfn.XLOOKUP('04_References'!$A$3,tblKPITargets[KPI_Name],tblKPITargets[Target_Value]),"Met","Below Target") -> Met | W356: =IF(tblOperations[[#This Row],[Quality_Pass_Rate]]>=_xlfn.XLOOKUP('04_References'!$A$4,tblKPITargets[KPI_Name],tblKPITargets[Target_Value]),"Met","Below Target") -> Met | X356: =IF(tblOperations[[#This Row],[Average_Completion_Days]]<=_xlfn.XLOOKUP('04_References'!$A$7,tblKPITargets[KPI_Name],tblKPITargets[Target_Value]),"Met","Below Target") -> Met | Y356: =IF(tblOperations[[#This Row],[Closing_Backlog]]<=_xlfn.XLOOKUP('04_References'!$A$8,tblKPITargets[KPI_Name],tblKPITargets[Target_Value]),"Met","Below Target") -> Met
A357: OPS-100356 | B357: 46037 | C357: South West | D357: Workplace Projects | E357: 0 | F357: 34 | G357: 34 | H357: 34 | I357: 0 | J357: 0 | K357: 0 | L357: 1.9 | M357: 0.918 | N357: 0.983 | O357: 4.6 | P357: 0.673 | Q357: 1 | R357: =TRIM(tblOperations[[#This Row],[Region]]) -> South West | S357: =TRIM(tblOperations[[#This Row],[Team]]) -> Workplace Projects | T357: =_xlfn.XLOOKUP(R357,tblRegionReference[Region],tblRegionReference[Area],"Not Found") -> South | U357: =IF(tblOperations[[#This Row],[Completion_Rate]]>=_xlfn.XLOOKUP("Completion Rate",tblKPITargets[KPI_Name],tblKPITargets[Target_Value]),"Met","Below Target") -> Met | V357: =IF(tblOperations[[#This Row],[SLA_Compliance]]>=_xlfn.XLOOKUP('04_References'!$A$3,tblKPITargets[KPI_Name],tblKPITargets[Target_Value]),"Met","Below Target") -> Below Target | W357: =IF(tblOperations[[#This Row],[Quality_Pass_Rate]]>=_xlfn.XLOOKUP('04_References'!$A$4,tblKPITargets[KPI_Name],tblKPITargets[Target_Value]),"Met","Below Target") -> Met | X357: =IF(tblOperations[[#This Row],[Average_Completion_Days]]<=_xlfn.XLOOKUP('04_References'!$A$7,tblKPITargets[KPI_Name],tblKPITargets[Target_Value]),"Met","Below Target") -> Met | Y357: =IF(tblOperations[[#This Row],[Closing_Backlog]]<=_xlfn.XLOOKUP('04_References'!$A$8,tblKPITargets[KPI_Name],tblKPITargets[Target_Value]),"Met","Below Target") -> Met
A358: OPS-100357 | B358: 46037 | C358: South East | D358: Workplace Services | E358: 11 | F358: 49 | G358: 60 | H358: 57 | I358: 3 | J358: 1 | K358: 0 | L358: 1.8 | M358: 0.942 | N358: 0.972 | O358: 4.4 | P358: 0.669 | Q358: 0.95 | R358: =TRIM(tblOperations[[#This Row],[Region]]) -> South East | S358: =TRIM(tblOperations[[#This Row],[Team]]) -> Workplace Services | T358: =_xlfn.XLOOKUP(R358,tblRegionReference[Region],tblRegionReference[Area],"Not Found") -> South | U358: =IF(tblOperations[[#This Row],[Completion_Rate]]>=_xlfn.XLOOKUP("Completion Rate",tblKPITargets[KPI_Name],tblKPITargets[Target_Value]),"Met","Below Target") -> Met | V358: =IF(tblOperations[[#This Row],[SLA_Compliance]]>=_xlfn.XLOOKUP('04_References'!$A$3,tblKPITargets[KPI_Name],tblKPITargets[Target_Value]),"Met","Below Target") -> Met | W358: =IF(tblOperations[[#This Row],[Quality_Pass_Rate]]>=_xlfn.XLOOKUP('04_References'!$A$4,tblKPITargets[KPI_Name],tblKPITargets[Target_Value]),"Met","Below Target") -> Met | X358: =IF(tblOperations[[#This Row],[Average_Completion_Days]]<=_xlfn.XLOOKUP('04_References'!$A$7,tblKPITargets[KPI_Name],tblKPITargets[Target_Value]),"Met","Below Target") -> Met | Y358: =IF(tblOperations[[#This Row],[Closing_Backlog]]<=_xlfn.XLOOKUP('04_References'!$A$8,tblKPITargets[KPI_Name],tblKPITargets[Target_Value]),"Met","Below Target") -> Met
A359: OPS-100358 | B359: 46037 | C359: South East | D359: Facilities Response | E359: 388 | F359: 47 | G359: 435 | H359: 21 | I359: 414 | J359: 0 | K359: 0 | L359: 8 | M359: 0.6 | N359: 0.982 | O359: 2.5 | P359: 0.751 | Q359: 0.048 | R359: =TRIM(tblOperations[[#This Row],[Region]]) -> South East | S359: =TRIM(tblOperations[[#This Row],[Team]]) -> Facilities Response | T359: =_xlfn.XLOOKUP(R359,tblRegionReference[Region],tblRegionReference[Area],"Not Found") -> South | U359: =IF(tblOperations[[#This Row],[Completion_Rate]]>=_xlfn.XLOOKUP("Completion Rate",tblKPITargets[KPI_Name],tblKPITargets[Target_Value]),"Met","Below Target") -> Below Target | V359: =IF(tblOperations[[#This Row],[SLA_Compliance]]>=_xlfn.XLOOKUP('04_References'!$A$3,tblKPITargets[KPI_Name],tblKPITargets[Target_Value]),"Met","Below Target") -> Below Target | W359: =IF(tblOperations[[#This Row],[Quality_Pass_Rate]]>=_xlfn.XLOOKUP('04_References'!$A$4,tblKPITargets[KPI_Name],tblKPITargets[Target_Value]),"Met","Below Target") -> Met | X359: =IF(tblOperations[[#This Row],[Average_Completion_Days]]<=_xlfn.XLOOKUP('04_References'!$A$7,tblKPITargets[KPI_Name],tblKPITargets[Target_Value]),"Met","Below Target") -> Below Target | Y359: =IF(tblOperations[[#This Row],[Closing_Backlog]]<=_xlfn.XLOOKUP('04_References'!$A$8,tblKPITargets[KPI_Name],tblKPITargets[Target_Value]),"Met","Below Target") -> Below Target
A360: OPS-100359 | B360: 46037 | C360: South East | D360: Estates Support | E360: 12 | F360: 36 | G360: 48 | H360: 48 | I360: 0 | J360: 1 | K360: 0 | L360: 1.8 | M360: 0.887 | N360: 0.987 | O360: 4.7 | P360: 0.695 | Q360: 1 | R360: =TRIM(tblOperations[[#This Row],[Region]]) -> South East | S360: =TRIM(tblOperations[[#This Row],[Team]]) -> Estates Support | T360: =_xlfn.XLOOKUP(R360,tblRegionReference[Region],tblRegionReference[Area],"Not Found") -> South | U360: =IF(tblOperations[[#This Row],[Completion_Rate]]>=_xlfn.XLOOKUP("Completion Rate",tblKPITargets[KPI_Name],tblKPITargets[Target_Value]),"Met","Below Target") -> Met | V360: =IF(tblOperations[[#This Row],[SLA_Compliance]]>=_xlfn.XLOOKUP('04_References'!$A$3,tblKPITargets[KPI_Name],tblKPITargets[Target_Value]),"Met","Below Target") -> Below Target | W360: =IF(tblOperations[[#This Row],[Quality_Pass_Rate]]>=_xlfn.XLOOKUP('04_References'!$A$4,tblKPITargets[KPI_Name],tblKPITargets[Target_Value]),"Met","Below Target") -> Met | X360: =IF(tblOperations[[#This Row],[Average_Completion_Days]]<=_xlfn.XLOOKUP('04_References'!$A$7,tblKPITargets[KPI_Name],tblKPITargets[Target_Value]),"Met","Below Target") -> Met | Y360: =IF(tblOperations[[#This Row],[Closing_Backlog]]<=_xlfn.XLOOKUP('04_References'!$A$8,tblKPITargets[KPI_Name],tblKPITargets[Target_Value]),"Met","Below Target") -> Met
A361: OPS-100360 | B361: 46037 | C361: South East | D361: Workplace Projects | E361: 143 | F361: 30 | G361: 173 | H361: 23 | I361: 150 | J361: 0 | K361: 0 | L361: 8 | M361: 0.6 | N361: 1 | O361: 2.5 | P361: 0.719 | Q361: 0.133 | R361: =TRIM(tblOperations[[#This Row],[Region]]) -> South East | S361: =TRIM(tblOperations[[#This Row],[Team]]) -> Workplace Projects | T361: =_xlfn.XLOOKUP(R361,tblRegionReference[Region],tblRegionReference[Area],"Not Found") -> South | U361: =IF(tblOperations[[#This Row],[Completion_Rate]]>=_xlfn.XLOOKUP("Completion Rate",tblKPITargets[KPI_Name],tblKPITargets[Target_Value]),"Met","Below Target") -> Below Target | V361: =IF(tblOperations[[#This Row],[SLA_Compliance]]>=_xlfn.XLOOKUP('04_References'!$A$3,tblKPITargets[KPI_Name],tblKPITargets[Target_Value]),"Met","Below Target") -> Below Target | W361: =IF(tblOperations[[#This Row],[Quality_Pass_Rate]]>=_xlfn.XLOOKUP('04_References'!$A$4,tblKPITargets[KPI_Name],tblKPITargets[Target_Value]),"Met","Below Target") -> Met | X361: =IF(tblOperations[[#This Row],[Average_Completion_Days]]<=_xlfn.XLOOKUP('04_References'!$A$7,tblKPITargets[KPI_Name],tblKPITargets[Target_Value]),"Met","Below Target") -> Below Target | Y361: =IF(tblOperations[[#This Row],[Closing_Backlog]]<=_xlfn.XLOOKUP('04_References'!$A$8,tblKPITargets[KPI_Name],tblKPITargets[Target_Value]),"Met","Below Target") -> Below Target
A362: OPS-100361 | B362: 46037 | C362: Wales | D362: Workplace Services | E362: 198 | F362: 47 | G362: 245 | H362: 24 | I362: 221 | J362: 0 | K362: 0 | L362: 8 | M362: 0.6 | N362: 0.972 | O362: 2.5 | P362: 0.771 | Q362: 0.098 | R362: =TRIM(tblOperations[[#This Row],[Region]]) -> Wales | S362: =TRIM(tblOperations[[#This Row],[Team]]) -> Workplace Services | T362: =_xlfn.XLOOKUP(R362,tblRegionReference[Region],tblRegionReference[Area],"Not Found") -> Wales | U362: =IF(tblOperations[[#This Row],[Completion_Rate]]>=_xlfn.XLOOKUP("Completion Rate",tblKPITargets[KPI_Name],tblKPITargets[Target_Value]),"Met","Below Target") -> Below Target | V362: =IF(tblOperations[[#This Row],[SLA_Compliance]]>=_xlfn.XLOOKUP('04_References'!$A$3,tblKPITargets[KPI_Name],tblKPITargets[Target_Value]),"Met","Below Target") -> Below Target | W362: =IF(tblOperations[[#This Row],[Quality_Pass_Rate]]>=_xlfn.XLOOKUP('04_References'!$A$4,tblKPITargets[KPI_Name],tblKPITargets[Target_Value]),"Met","Below Target") -> Met | X362: =IF(tblOperations[[#This Row],[Average_Completion_Days]]<=_xlfn.XLOOKUP('04_References'!$A$7,tblKPITargets[KPI_Name],tblKPITargets[Target_Value]),"Met","Below Target") -> Below Target | Y362: =IF(tblOperations[[#This Row],[Closing_Backlog]]<=_xlfn.XLOOKUP('04_References'!$A$8,tblKPITargets[KPI_Name],tblKPITargets[Target_Value]),"Met","Below Target") -> Below Target
A363: OPS-100362 | B363: 46037 | C363: Wales | D363: Facilities Response | E363: 134 | F363: 37 | G363: 171 | H363: 30 | I363: 141 | J363: 0 | K363: 0 | L363: 8 | M363: 0.6 | N363: 1 | O363: 2.5 | P363: 0.706 | Q363: 0.175 | R363: =TRIM(tblOperations[[#This Row],[Region]]) -> Wales | S363: =TRIM(tblOperations[[#This Row],[Team]]) -> Facilities Response | T363: =_xlfn.XLOOKUP(R363,tblRegionReference[Region],tblRegionReference[Area],"Not Found") -> Wales | U363: =IF(tblOperations[[#This Row],[Completion_Rate]]>=_xlfn.XLOOKUP("Completion Rate",tblKPITargets[KPI_Name],tblKPITargets[Target_Value]),"Met","Below Target") -> Below Target | V363: =IF(tblOperations[[#This Row],[SLA_Compliance]]>=_xlfn.XLOOKUP('04_References'!$A$3,tblKPITargets[KPI_Name],tblKPITargets[Target_Value]),"Met","Below Target") -> Below Target | W363: =IF(tblOperations[[#This Row],[Quality_Pass_Rate]]>=_xlfn.XLOOKUP('04_References'!$A$4,tblKPITargets[KPI_Name],tblKPITargets[Target_Value]),"Met","Below Target") -> Met | X363: =IF(tblOperations[[#This Row],[Average_Completion_Days]]<=_xlfn.XLOOKUP('04_References'!$A$7,tblKPITargets[KPI_Name],tblKPITargets[Target_Value]),"Met","Below Target") -> Below Target | Y363: =IF(tblOperations[[#This Row],[Closing_Backlog]]<=_xlfn.XLOOKUP('04_References'!$A$8,tblKPITargets[KPI_Name],tblKPITargets[Target_Value]),"Met","Below Target") -> Below Target
A364: OPS-100363 | B364: 46037 | C364: Wales | D364: Estates Support | E364: 100 | F364: 57 | G364: 157 | H364: 27 | I364: 130 | J364: 0 | K364: 0 | L364: 8 | M364: 0.6 | N364: 0.98 | O364: 2.5 | P364: 0.755 | Q364: 0.172 | R364: =TRIM(tblOperations[[#This Row],[Region]]) -> Wales | S364: =TRIM(tblOperations[[#This Row],[Team]]) -> Estates Support | T364: =_xlfn.XLOOKUP(R364,tblRegionReference[Region],tblRegionReference[Area],"Not Found") -> Wales | U364: =IF(tblOperations[[#This Row],[Completion_Rate]]>=_xlfn.XLOOKUP("Completion Rate",tblKPITargets[KPI_Name],tblKPITargets[Target_Value]),"Met","Below Target") -> Below Target | V364: =IF(tblOperations[[#This Row],[SLA_Compliance]]>=_xlfn.XLOOKUP('04_References'!$A$3,tblKPITargets[KPI_Name],tblKPITargets[Target_Value]),"Met","Below Target") -> Below Target | W364: =IF(tblOperations[[#This Row],[Quality_Pass_Rate]]>=_xlfn.XLOOKUP('04_References'!$A$4,tblKPITargets[KPI_Name],tblKPITargets[Target_Value]),"Met","Below Target") -> Met | X364: =IF(tblOperations[[#This Row],[Average_Completion_Days]]<=_xlfn.XLOOKUP('04_References'!$A$7,tblKPITargets[KPI_Name],tblKPITargets[Target_Value]),"Met","Below Target") -> Below Target | Y364: =IF(tblOperations[[#This Row],[Closing_Backlog]]<=_xlfn.XLOOKUP('04_References'!$A$8,tblKPITargets[KPI_Name],tblKPITargets[Target_Value]),"Met","Below Target") -> Below Target
... A621: OPS-100620 | B621: 46051 | C621: Scotland | D621: Workplace Projects | E621: 0 | F621: 31 | G621: 31 | H621: 31 | I621: 0 | J621: 0 | K621: 0 | L621: 1.7 | M621: 0.954 | N621: 1 | O621: 4.7 | P621: 0.777 | Q621: 1 | R621: =TRIM(tblOperations[[#This Row],[Region]]) -> Scotland | S621: =TRIM(tblOperations[[#This Row],[Team]]) -> Workplace Projects | T621: =_xlfn.XLOOKUP(R621,tblRegionReference[Region],tblRegionReference[Area],"Not Found") -> North | U621: =IF(tblOperations[[#This Row],[Completion_Rate]]>=_xlfn.XLOOKUP("Completion Rate",tblKPITargets[KPI_Name],tblKPITargets[Target_Value]),"Met","Below Target") -> Met | V621: =IF(tblOperations[[#This Row],[SLA_Compliance]]>=_xlfn.XLOOKUP('04_References'!$A$3,tblKPITargets[KPI_Name],tblKPITargets[Target_Value]),"Met","Below Target") -> Met | W621: =IF(tblOperations[[#This Row],[Quality_Pass_Rate]]>=_xlfn.XLOOKUP('04_References'!$A$4,tblKPITargets[KPI_Name],tblKPITargets[Target_Value]),"Met","Below Target") -> Met | X621: =IF(tblOperations[[#This Row],[Average_Completion_Days]]<=_xlfn.XLOOKUP('04_References'!$A$7,tblKPITargets[KPI_Name],tblKPITargets[Target_Value]),"Met","Below Target") -> Met | Y621: =IF(tblOperations[[#This Row],[Closing_Backlog]]<=_xlfn.XLOOKUP('04_References'!$A$8,tblKPITargets[KPI_Name],tblKPITargets[Target_Value]),"Met","Below Target") -> Met
A622: OPS-100621 | B622: 46051 | C622: North East | D622: Workplace Services | E622: 0 | F622: 37 | G622: 37 | H622: 37 | I622: 0 | J622: 0 | K622: 0 | L622: 1.6 | N622: 1 | O622: 4.5 | P622: 0.692 | Q622: 1 | R622: =TRIM(tblOperations[[#This Row],[Region]]) -> North East | S622: =TRIM(tblOperations[[#This Row],[Team]]) -> Workplace Services | T622: =_xlfn.XLOOKUP(R622,tblRegionReference[Region],tblRegionReference[Area],"Not Found") -> North | U622: =IF(tblOperations[[#This Row],[Completion_Rate]]>=_xlfn.XLOOKUP("Completion Rate",tblKPITargets[KPI_Name],tblKPITargets[Target_Value]),"Met","Below Target") -> Met | V622: =IF(tblOperations[[#This Row],[SLA_Compliance]]>=_xlfn.XLOOKUP('04_References'!$A$3,tblKPITargets[KPI_Name],tblKPITargets[Target_Value]),"Met","Below Target") -> Below Target | W622: =IF(tblOperations[[#This Row],[Quality_Pass_Rate]]>=_xlfn.XLOOKUP('04_References'!$A$4,tblKPITargets[KPI_Name],tblKPITargets[Target_Value]),"Met","Below Target") -> Met | X622: =IF(tblOperations[[#This Row],[Average_Completion_Days]]<=_xlfn.XLOOKUP('04_References'!$A$7,tblKPITargets[KPI_Name],tblKPITargets[Target_Value]),"Met","Below Target") -> Met | Y622: =IF(tblOperations[[#This Row],[Closing_Backlog]]<=_xlfn.XLOOKUP('04_References'!$A$8,tblKPITargets[KPI_Name],tblKPITargets[Target_Value]),"Met","Below Target") -> Met
